Workbook

Sheet Zbiorczy
B1: wydatki | C1: przychody | D1: stan konta | E1: wydatki bez kosztów stałych | F1: zaoszczędzone | N1: zaoszczedzone log
A2: lipiec2020 | B2: =SUM(lipiec!B3:B90) -> 13428.1 | C2: =SUM(lipiec!E3:E23) -> 17932.17 | D2: =MINUS(C2 + lipiec!G3, B2) -> 20014.07 | E2: =B2 - lipiec!J1 -> 4826.1 | F2: =C2-B2 -> 4504.07 | N2: =IF(F2 > 0, LOG10(F2),0) -> 3.6536051
A3: sierpien2020 | B3: =SUM('sierpień'!$B$3:$B$100) -> 12007.07 | C3: =SUM('sierpień'!$E$3:$E$24) -> 17589 | D3: =MINUS(C3 + 'sierpień'!$G$3, $B3) -> 25596 | E3: =B3 - 'sierpień'!$J$1 -> 3929.07 | F3: =C3-B3 -> 5581.93 | N3: =IF(F3 > 0, LOG10(F3),0) -> 3.7467844
A4: wrzesień2020 | B4: =SUM('wrzesień'!$B$3:$B$100) -> 11402 | C4: =SUM('wrzesień'!$E$3:$E$24) -> 13591 | D4: =MINUS(C4 + 'wrzesień'!$G$3, $B4) -> 27785 | E4: =B4 - 'wrzesień'!$J$1 -> 3612 | F4: =C4-B4 -> 2189 | N4: =IF(F4 > 0, LOG10(F4),0) -> 3.3402458
A5: październik2020 | B5: =SUM('październik'!$B$3:$B$100) -> 14783 | C5: =SUM('październik'!$E$3:$E$24) -> 17972 | D5: =MINUS(C5 + 'październik'!$G$3, $B5) -> 30974 | E5: =B5 - 'październik'!$J$1 -> 4936 | F5: =C5-B5 -> 3189 | N5: =IF(F5 > 0, LOG10(F5),0) -> 3.5036545
A6: listopad2020 | B6: =SUM(listopad!$B$3:$B$100) -> 18573 | C6: =SUM(listopad!$F$3:$F$24) -> 17637 | D6: =MINUS(C6 + listopad!$H$3, $B6) -> 30038 | E6: =B6 - listopad!$K$1 -> 10447 | F6: =C6-B6 -> -936 | N6: =IF(F6 > 0, LOG10(F6),0) -> 0
A7: grudzien2020 | B7: =SUM('grudzień'!$B$3:$B$101) -> 16046 | C7: =SUM('grudzień'!$F$3:$F$24) -> 21955.62 | D7: =MINUS(C7 + 'grudzień'!$H$3, $B7) -> 35947.62 | E7: =B7 - 'grudzień'!$K$1 -> 10965 | F7: =C7-B7 -> 5909.62 | N7: =IF(F7 > 0, LOG10(F7),0) -> 3.7715596
A8: styczen2021 | B8: =SUM('styczeń'!$B$3:$B$101) -> 10262 | C8: =SUM('styczeń'!$F$3:$F$24) -> 16873.14 | D8: =MINUS(C8 + 'styczeń'!$H$3, $B8) -> 42558.76 | E8: =B8 - 'styczeń'!$K$1 -> 3714 | F8: =C8-B8 -> 6611.14 | N8: =IF(F8 > 0, LOG10(F8),0) -> 3.8202764
A9: luty2021 | B9: =SUM(luty2021!$B$3:$B$101) -> 13917 | C9: =SUM(luty2021!$F$3:$F$24) -> 16038.41 | D9: =MINUS(C9 + luty2021!$H$3, $B9) -> 44680.17 | E9: =B9 - luty2021!$K$1 -> 7947 | F9: =C9-B9 -> 2121.41 | N9: =IF(F9 > 0, LOG10(F9),0) -> 3.3266246
A10: marzec2021 | B10: =SUM(marzec2021!$B$3:$B$101) -> 12114 | C10: =SUM(marzec2021!$F$3:$F$24) -> 16050.52 | D10: =MINUS(C10 + marzec2021!$H$3, $B10) -> 48616.69 | E10: =B10 - marzec2021!$K$1 -> 5880 | F10: =C10-B10 -> 3936.52 | N10: =IF(F10 > 0, LOG10(F10),0) -> 3.5951125
A11: kwiecień2021 | B11: =SUM('kwiecień2021'!$B$3:$B$101) -> 14279.2 | C11: =SUM('kwiecień2021'!$F$3:$F$24) -> 21303 | D11: =MINUS(C11 + 'kwiecień2021'!$H$3, $B11) -> 55640.49 | E11: =B11 - 'kwiecień2021'!$K$1 -> 5432.2 | F11: =C11-B11 -> 7023.8 | N11: =IF(F11 > 0, LOG10(F11),0) -> 3.8465721
A12: 44317 | B12: =SUM('maj2021'!$B$3:$B$101) -> 19423 | C12: =SUM('maj2021'!$F$3:$F$24) -> 20368.8 | D12: =MINUS(C12 + 'maj2021'!$H$3, $B12) -> 56586.29 | E12: =B12 - 'maj2021'!$K$1 -> 11945 | F12: =C12-B12 -> 945.8 | N12: =IF(F12 > 0, LOG10(F12),0) -> 2.9757993
A13: 44348 | B13: =SUM(czerwiec2021!$B$3:$B$101) -> 16507 | C13: =SUM(czerwiec2021!$F$3:$F$24) -> 25066 | D13: =MINUS(C13 + czerwiec2021!$H$3, $B13) -> 65145.29 | E13: =B13 - czerwiec2021!$K$1 -> 5630 | F13: =C13-B13 -> 8559 | N13: =IF(F13 > 0, LOG10(F13),0) -> 3.932423
A14: 44378 | B14: =SUM(lipiec2021!$B$3:$B$101) -> 14228 | C14: =SUM(lipiec2021!$F$3:$F$24) -> 20368 | D14: =MINUS(C14 + lipiec2021!$H$3, $B14) -> 71285.29 | E14: =B14 - lipiec2021!$K$1 -> 4342 | F14: =C14-B14 -> 6140 | N14: =IF(F14 > 0, LOG10(F14),0) -> 3.7881684
A15: 44409 | B15: =SUM('sierpień2021'!$B$3:$B$101) -> 17061 | C15: =SUM('sierpień2021'!$F$3:$F$24) -> 19750 | D15: =MINUS(C15 + 'sierpień2021'!$H$3, $B15) -> 73974.29 | E15: =B15 - 'sierpień2021'!$K$1 -> 8823 | F15: =C15-B15 -> 2689 | N15: =IF(F15 > 0, LOG10(F15),0) -> 3.4295908
A16: 44440 | B16: =SUM('wrzesień2021'!$B$3:$B$101) -> 16055 | C16: =SUM('wrzesień2021'!$F$3:$F$24) -> 17527 | D16: =MINUS(C16 + 'wrzesień2021'!$H$3, $B16) -> 75446.29 | E16: =B16 - 'wrzesień2021'!$K$1 -> 8672 | F16: =C16-B16 -> 1472 | N16: =IF(F16 > 0, LOG10(F16),0) -> 3.1679078
A17: 44470 | B17: =SUM('październik2021'!$B$3:$B$101) -> 19628 | C17: =SUM('październik2021'!$F$3:$F$24) -> 19710 | D17: =MINUS(C17 + 'październik2021'!$H$3, $B17) -> 75528.29 | E17: =B17 - 'październik2021'!$K$1 -> 12018 | F17: =C17-B17 -> 82 | N17: =IF(F17 > 0, LOG10(F17),0) -> 1.9138139
A18: 44501 | B18: =SUM(listopad2021!$B$3:$B$101) -> 16500 | C18: =SUM(listopad2021!$F$3:$F$24) -> 18304 | D18: =MINUS(C18 + listopad2021!$H$3, $B18) -> 77332.29 | E18: =B18 - listopad2021!$K$1 -> 10148 | F18: =C18-B18 -> 1804 | N18: =IF(F18 > 0, LOG10(F18),0) -> 3.2562365
A19: 44531 | B19: =SUM('grudzień2021'!$B$3:$B$101) -> 22346 | C19: =SUM('grudzień2021'!$F$3:$F$24) -> 22032 | D19: =MINUS(C19 + 'grudzień2021'!$H$3, $B19) -> 77018.29 | E19: =B19 - 'grudzień2021'!$K$1 -> 13499 | F19: =C19-B19 -> -314 | N19: =IF(F19 > 0, LOG10(F19),0) -> 0
A20: 44562 | B20: =SUM('styczeń2022'!$B$3:$B$100) -> 20011 | C20: =SUM('styczeń2022'!$F$3:$F$24) -> 23873 | D20: =MINUS(C20 + 'styczeń2022'!$H$3, $B20) -> 80880.29 | E20: =B20 - 'styczeń2022'!$K$1 -> 9765 | F20: =C20-B20 -> 3862 | N20: =IF(F20 > 0, LOG10(F20),0) -> 3.5868123
A21: 44593 | B21: =SUM(luty2022!$B$3:$B$100) -> 26135 | C21: =SUM(luty2022!$F$3:$F$24) -> 21708 | D21: =MINUS(C21 + luty2022!$H$3, $B21) -> 76453.29 | E21: =B21 - luty2022!$K$1 -> 17483 | F21: =C21-B21 -> -4427 | N21: =IF(F21 > 0, LOG10(F21),0) -> 0
A22: 44622 | B22: =SUM(marzec2022!$B$3:$B$100) -> 13063 | C22: =SUM(marzec2022!$F$3:$F$24) -> 16800 | D22: =MINUS(C22 + marzec2022!$H$3, $B22) -> 80190.29 | E22: =B22 - marzec2022!$K$1 -> 6001 | F22: =C22-B22 -> 3737 | N22: =IF(F22 > 0, LOG10(F22),0) -> 3.5725231
A23: 44654 | B23: =SUM('kwiecień2022'!$B$3:$B$100) -> 18726 | C23: =SUM('kwiecień2022'!$F$3:$F$24) -> 21050 | D23: =MINUS(C23 + 'kwiecień2022'!$H$3, $B23) -> 82514.29 | E23: =B23 - 'kwiecień2022'!$K$1 -> 12331 | F23: =C23-B23 -> 2324 | N23: =IF(F23 > 0, LOG10(F23),0) -> 3.3662361
A24: 44682 | B24: =SUM('maj2022'!$B$3:$B$100) -> 41614 | C24: =SUM('maj2022'!$F$3:$F$24) -> 18236 | D24: =MINUS(C24 + 'maj2022'!$H$3, $B24) -> 59136.29 | E24: =B24 - 'maj2022'!$K$1 -> 34112 | F24: =C24-B24 -> -23378 | N24: =IF(F24 > 0, LOG10(F24),0) -> 0
A25: czerwiec2022 | B25: =SUM(czerwiec2022!$B$3:$B$100) -> 14297 | C25: =SUM(czerwiec2022!$F$3:$F$24) -> 22880 | D25: =MINUS(C25 + czerwiec2022!$H$3, $B25) -> 67719.29 | E25: =B25 - czerwiec2022!$K$1 -> 7149 | F25: =C25-B25 -> 8583 | N25: =IF(F25 > 0, LOG10(F25),0) -> 3.9336391
A26: lipiec2022 | B26: =SUM(lipiec2022!$B$3:$B$100) -> 18695.29 | C26: =SUM(lipiec2022!$F$3:$F$24) -> 23464 | D26: =MINUS(C26 + lipiec2022!$H$3, $B26) -> 72488 | E26: =B26 - lipiec2022!$K$1 -> 11830.29 | F26: =C26-B26 -> 4768.71 | N26: =IF(F26 > 0, LOG10(F26),0) -> 3.6784009
A27: sierpien2022 | B27: =SUM(sierpien2022!$B$3:$B$96) -> 22741 | C27: =SUM(sierpien2022!$F$3:$F$24) -> 23489 | D27: =MINUS(C27 + sierpien2022!$H$3, $B27) -> 73236 | E27: =B27 - sierpien2022!$K$1 -> 16055 | F27: =C27-B27 -> 748 | N27: =IF(F27 > 0, LOG10(F27),0) -> 2.8739016
A28: wrzesien2022 | B28: =SUM(wrzesien2022!$B$3:$B$100) -> 16497 | C28: =SUM(wrzesien2022!$F$3:$F$24) -> 23099 | D28: =MINUS(C28 + wrzesien2022!$H$3, $B28) -> 79838 | E28: =B28 - wrzesien2022!$K$1 -> 7691 | F28: =C28-B28 -> 6602 | N28: =IF(F28 > 0, LOG10(F28),0) -> 3.8196755
A29: pazdziernik2022 | B29: =SUM(pazdziernik2022!$B$3:$B$100) -> 17791 | C29: =SUM(pazdziernik2022!$F$3:$F$24) -> 26340 | D29: =MINUS(C29 + pazdziernik2022!$H$3, $B29) -> 88387 | E29: =B29 - pazdziernik2022!$K$1 -> 9148 | F29: =C29-B29 -> 8549 | N29: =IF(F29 > 0, LOG10(F29),0) -> 3.9319153
A30: listopad2022 | B30: =SUM(listopad2022!$B$3:$B$100) -> 17998 | C30: =SUM(listopad2022!$F$3:$F$24) -> 22111 | D30: =MINUS(C30 + listopad2022!$H$3, $B30) -> 92500 | E30: =B30 - listopad2022!$K$1 -> 8419 | F30: =C30-B30 -> 4113 | N30: =IF(F30 > 0, LOG10(F30),0) -> 3.6141587
A31: grudzien2022 | B31: =SUM(grudzien2022!$B$3:$B$97) -> 54198 | C31: =SUM(grudzien2022!$F$3:$F$23) -> 32258 | D31: =MINUS(C31 + grudzien2022!$H$3, $B31) -> 70560 | E31: =B31 - grudzien2022!$K$1 -> 39878.51 | F31: =C31-B31 -> -21940 | N31: =IF(F31 > 0, LOG10(F31),0) -> 0
A32: styczen2023 | B32: =SUM(styczen2023!$B$3:$B$97) -> 24603 | C32: =SUM(styczen2023!$F$3:$F$23) -> 53932 | D32: =MINUS(C32 + styczen2023!$H$3, $B32) -> 99889 | E32: =B32 - styczen2023!$K$1 -> 13512 | F32: =C32-B32 -> 29329 | N32: =IF(F32 > 0, LOG10(F32),0) -> 4.4672973
A33: luty2023 | B33: =SUM(luty2023!$B$3:$B$97) -> 28398.33 | C33: =SUM(luty2023!$F$3:$F$23) -> 30996 | D33: =MINUS(C33 + luty2023!$H$3, $B33) -> 102486.67 | E33: =B33 - luty2023!$K$1 -> 10162.33 | F33: =C33-B33 -> 2597.67 | N33: =IF(F33 > 0, LOG10(F33),0) -> 3.414584
A34: marzec2023 | B34: =SUM(marzec2023!$B$3:$B$97) -> 16663.32 | C34: =SUM(marzec2023!$F$3:$F$23) -> 9489 | D34: =MINUS(C34 + marzec2023!$H$3, $B34) -> 95312.35 | E34: =B34 - marzec2023!$K$1 -> -22928.32 | F34: =C34-B34 -> -7174.32 | N34: =IF(F34 > 0, LOG10(F34),0) -> 0
A35: kwiecien2023 | B35: =SUM(kwiecien2023!$B$3:$B$97) -> 27464.67 | C35: =SUM(kwiecien2023!$F$3:$F$23) -> 35017 | D35: =MINUS(C35 + kwiecien2023!$H$3, $B35) -> 102864.68 | E35: =B35 - kwiecien2023!$K$1 -> 13609.67 | F35: =C35-B35 -> 7552.33 | N35: =IF(F35 > 0, LOG10(F35),0) -> 3.878081
A36: 45047 | B36: =SUM('maj2023'!$B$3:$B$97) -> 24096 | C36: =SUM('maj2023'!$F$3:$F$23) -> 29293 | D36: =MINUS(C36 + 'maj2023'!$H$3, $B36) -> 108061.68 | E36: =B36 - 'maj2023'!$K$1 -> 13812 | F36: =C36-B36 -> 5197 | N36: =IF(F36 > 0, LOG10(F36),0) -> 3.7157527
A37: 45078 | B37: =SUM(czerwiec2023!$B$3:$B$97) -> 25996 | C37: =SUM(czerwiec2023!$F$3:$F$23) -> 35024 | D37: =MINUS(C37 + czerwiec2023!$H$3, $B37) -> 117089.68 | E37: =B37 - czerwiec2023!$K$1 -> 12442 | F37: =C37-B37 -> 9028 | N37: =IF(F37 > 0, LOG10(F37),0) -> 3.9555915
A38: 45108 | B38: =SUM(lipiec2023!$B$3:$B$97) -> 29459 | C38: =SUM(lipiec2023!$F$3:$F$23) -> 32834 | D38: =MINUS(C38 + lipiec2023!$H$3, $B38) -> 120464.68 | E38: =B38 - lipiec2023!$K$1 -> 16605 | F38: =C38-B38 -> 3375 | N38: =IF(F38 > 0, LOG10(F38),0) -> 3.5282738
A39: 45139 | B39: =SUM(sierpien2023!$B$3:$B$97) -> 32271.91 | C39: =SUM(sierpien2023!$F$3:$F$23) -> 39306.23 | D39: =MINUS(C39 + sierpien2023!$H$3, $B39) -> 127499 | E39: =B39 - sierpien2023!$K$1 -> 17426.91 | F39: =C39-B39 -> 7034.32 | N39: =IF(F39 > 0, LOG10(F39),0) -> 3.8472221
A40: 45170 | B40: =SUM(wrzesien2023!$B$3:$B$97) -> 27495 | C40: =SUM(wrzesien2023!$F$3:$F$23) -> 33517 | D40: =MINUS(C40 + wrzesien2023!$H$3, $B40) -> 133521 | E40: =B40 - wrzesien2023!$K$1 -> 13273 | F40: =C40-B40 -> 6022 | N40: =IF(F40 > 0, LOG10(F40),0) -> 3.7797408
...

Sheet pazdziernik2025
E1: Przychody | H1: Stan konta na początku miesiąca | J1: Koszty stałe | K1: =SUM(J3:J991) -> 2443
A2: kategoria | B2: kwota | C2: opis | D2: data
E3: sml | F3: 35234 | H3: =Zbiorczy!D64 -> 164457.22 | J3: =SUMIF($A$3:A$197, K3, B$3:B$197) -> 0 | K3: zus | M3: =SUMIF($A$3:A$197, N3, B$3:B$197) -> 416.27 | N3: biedronka | R3: kategoria | S3: kwota | T3: opis | U3: data
A4: przejazdy | B4: 5 | C4: Nazwa odbiorcy: MOBILE-TRAFFIC-DATA SP. Z O. O. Adres odbiorcy: UL. DRUŻBICKIEGO 11 61-693 POZNAŃ Tytuł: ZAKUP BILETU KOMUNIKACYJNEGO W APLI KACJI IKO Referencje własne zleceniodawcy: 176171147909 (5.00 PLN) | D4: 45943 | E4: skąd? | J4: =SUMIF($A$3:A$197, K4, B$3:B$197) -> 0 | K4: PIT36 | M4: =SUMIF($A$3:A$197, N4, B$3:B$197) -> 10.5 | N4: żabka | R4: kawa | S4: 23.9 | T4: Tytuł: 74838495271331029792336 Lokalizacja: Adres: PL SBX POZNAN KAPONIERA Miasto: POZNAN Kraj: POLSKA Data wykonania operacji: 2025-09-28 02:00 Oryginalna kwota operacji: 23.90 Numer karty: 425125******0264 (23.90 PLN) | U4: 45930
A5: przejazdy | B5: 5 | C5: Nazwa odbiorcy: MOBILE-TRAFFIC-DATA SP. Z O. O. Adres odbiorcy: UL. DRUŻBICKIEGO 11 61-693 POZNAŃ Tytuł: ZAKUP BILETU KOMUNIKACYJNEGO W APLI KACJI IKO Referencje własne zleceniodawcy: 176170813393 (5.00 PLN) | D5: 45943 | E5: sml prezent | J5: =SUMIF($A$3:A$197, K5, B$3:B$197) -> 0 | K5: VAT | M5: =SUMIF($A$3:A$197, N5, B$3:B$197) -> 2805.45 | N5: auto | R5: kawa | S5: 36 | T5: Tytuł: 74838495271330989542053 Lokalizacja: Adres: AGRAWKA Miasto: POZNAN Kraj: POLSKA Data wykonania operacji: 2025-09-28 02:00 Oryginalna kwota operacji: 36.00 Numer karty: 425125******0264 (36.00 PLN) | U5: 45930
A6: biedronka | B6: 15.48 | C6: Tytuł: 000498849 74230785285177549416712 Lokalizacja: Adres: NETTO 5304 SCO K.3 Miasto: POZNAN Kraj: POLSKA Data wykonania operacji: 2025-10-11 02:00 Oryginalna kwota operacji: 15.48 Numer karty: 425125******0264 (15.48 PLN) | D6: 45943 | J6: =SUMIF($A$3:A$197, K6, B$3:B$197) -> 2443 | K6: mieszkanie | M6: =SUMIF($A$3:A$197, N6, B$3:B$197) -> 0 | N6: paliwo | R6: mieszkanie | S6: 320 | T6: Rachunek odbiorcy: 73 1090 2372 0000 0001 1332 9442 Nazwa odbiorcy: MARTA SZCZYGIEŁ Tytuł: PRZELEW NA TELEFON OD: 48796555364 DO: 486*****967 (320.00 PLN) | U6: 45929
A7: biedronka | B7: 26 | C7: Tytuł: 000498849 74230785285177534219758 Lokalizacja: Adres: STRONA Miasto: POZNAN Kraj: POLSKA Data wykonania operacji: 2025-10-11 02:00 Oryginalna kwota operacji: 26.00 Numer karty: 425125******0264 (26.00 PLN) | D7: 45943 | J7: =SUMIF($A$3:A$197, K7, B$3:B$197) -> 0 | K7: kredyt | M7: =SUMIF($A$3:A$197, N7, B$3:B$197) -> 1673.64 | N7: fun | R7: przejazdy | S7: 5 | T7: Nazwa odbiorcy: MOBILE-TRAFFIC-DATA SP. Z O. O. Adres odbiorcy: UL. DRUŻBICKIEGO 11 61-693 POZNAŃ Tytuł: ZAKUP BILETU KOMUNIKACYJNEGO W APLI KACJI IKO Referencje własne zleceniodawcy: 176117332131 (5.00 PLN) | U7: 45929
A8: biuro | B8: 18.9 | C8: Tytuł: 010061097 74169505284622844453512 Lokalizacja: Adres: FHU OFFICE ART SCHOOL SC Miasto: POZNAN Kraj: POLSKA Data wykonania operacji: 2025-10-11 02:00 Oryginalna kwota operacji: 18.90 Numer karty: 425125******0264 (18.90 PLN) | D8: 45943 | M8: =SUMIF($A$3:A$197, N8, B$3:B$197) -> 2805.45 | N8: auto | R8: przejazdy | S8: 5 | T8: Nazwa odbiorcy: MOBILE-TRAFFIC-DATA SP. Z O. O. Adres odbiorcy: UL. DRUŻBICKIEGO 11 61-693 POZNAŃ Tytuł: ZAKUP BILETU KOMUNIKACYJNEGO W APLI KACJI IKO Referencje własne zleceniodawcy: 176117028129 (5.00 PLN) | U8: 45929
A9: fun | B9: 129.99 | C9: Tytuł: 010066928 74056285284109308718312 Lokalizacja: Adres: APPLE.COM/BILL Miasto: APPLE.COM/BIL Kraj: IRLANDIA Data wykonania operacji: 2025-10-11 02:00 Oryginalna kwota operacji: 129.99 Numer karty: 425125******0264 (129.99 PLN) | D9: 45943 | M9: =SUMIF($A$3:A$197, N9, B$3:B$197) -> 0 | N9: restauracje | R9: restauracje | S9: 33 | T9: Tytuł: 010046551 74230105270060695629718 Lokalizacja: Adres: PATILA DONER KEBAP Miasto: WARSZAWA Kraj: POLSKA Data wykonania operacji: 2025-09-27 02:00 Oryginalna kwota operacji: 33.00 Numer karty: 425125******0264 (33.00 PLN) | U9: 45929
A10: biedronka | B10: 4.5 | C10: Tytuł: 010061097 74169505283652832785030 Lokalizacja: Adres: FABRYKA FORMY POZNAN BALT Miasto: POZNAN Kraj: POLSKA Data wykonania operacji: 2025-10-10 02:00 Oryginalna kwota operacji: 4.50 Numer karty: 425125******0264 (4.50 PLN) | D10: 45942 | R10: kawa | S10: 22 | T10: Tytuł: 74838495270330831227797 Lokalizacja: Adres: ALL GOOD S.A. KAWIARNIA Miasto: WARSZAWA Kraj: POLSKA Data wykonania operacji: 2025-09-27 02:00 Oryginalna kwota operacji: 22.00 Numer karty: 425125******0264 (22.00 PLN) | U10: 45929
A11: biedronka | B11: 25 | C11: Tytuł: 010061097 74169505283652832784975 Lokalizacja: Adres: FABRYKA FORMY POZNAN BALT Miasto: POZNAN Kraj: POLSKA Data wykonania operacji: 2025-10-10 02:00 Oryginalna kwota operacji: 25.00 Numer karty: 425125******0264 (25.00 PLN) | D11: 45942 | R11: biedronka | S11: 59.98 | T11: Tytuł: 74838495270330948540132 Lokalizacja: Adres: ME M03 02 Miasto: POZNAN Kraj: POLSKA Data wykonania operacji: 2025-09-27 02:00 Oryginalna kwota operacji: 59.98 Numer karty: 425125******0264 (59.98 PLN) | U11: 45929
A12: kawa | B12: 75 | C12: Tytuł: 74810315283172414272346 Lokalizacja: Adres: Mowish Mash Miasto: Poznan Kraj: POLSKA Data wykonania operacji: 2025-10-10 02:00 Oryginalna kwota operacji: 75.00 Numer karty: 425125******0264 (75.00 PLN) | D12: 45942 | R12: biedronka | S12: 376.72 | T12: Tytuł: 74838495271330946294426 Lokalizacja: Adres: LIDL GLOGOWSKA Miasto: Poznan Kraj: POLSKA Data wykonania operacji: 2025-09-27 02:00 Oryginalna kwota operacji: 376.72 Numer karty: 425125******0264 (376.72 PLN) | U12: 45929
A13: fun | B13: 18 | C13: Tytuł: 74810315283172414782427 Lokalizacja: Adres: Maselko Miasto: Poznan Kraj: POLSKA Data wykonania operacji: 2025-10-10 02:00 Oryginalna kwota operacji: 18.00 Numer karty: 425125******0264 (18.00 PLN) | D13: 45942 | R13: kawa | S13: 51 | T13: Tytuł: 74838495270330817887705 Lokalizacja: Adres: ALL GOOD S.A. KAWIARNIA Miasto: WARSZAWA Kraj: POLSKA Data wykonania operacji: 2025-09-27 02:00 Oryginalna kwota operacji: 51.00 Numer karty: 425125******0264 (51.00 PLN) | U13: 45929
A14: fun | B14: 20.99 | C14: Tytuł: 010059127 74062945282143299379290 Lokalizacja: Adres: www.inpost.pl Miasto: KRAKOW Kraj: POLSKA Data wykonania operacji: 2025-10-09 02:00 Oryginalna kwota operacji: 20.99 Numer karty: 425125******0264 (20.99 PLN) | D14: 45941 | R14: auto | S14: 4.5 | T14: Tytuł: 74810315270171203357685 Lokalizacja: Adres: WARS Automat vendingowy Miasto: Warszawa Kraj: POLSKA Data wykonania operacji: 2025-09-27 02:00 Oryginalna kwota operacji: 4.50 Numer karty: 425125******0264 (4.50 PLN) | U14: 45929
A15: biedronka | B15: 25 | C15: Tytuł: 000498849 74230785282177354256305 Lokalizacja: Adres: STRONA Miasto: POZNAN Kraj: POLSKA Data wykonania operacji: 2025-10-09 02:00 Oryginalna kwota operacji: 25.00 Numer karty: 425125******0264 (25.00 PLN) | D15: 45941 | R15: auto | S15: 4.5 | T15: Tytuł: 74810315270171203487599 Lokalizacja: Adres: WARS Automat vendingowy Miasto: Warszawa Kraj: POLSKA Data wykonania operacji: 2025-09-27 02:00 Oryginalna kwota operacji: 4.50 Numer karty: 425125******0264 (4.50 PLN) | U15: 45929
A16: żabka | B16: 6 | C16: Tytuł: 000498849 74230785282177375805239 Lokalizacja: Adres: ZABKA Z0685 K.1 Miasto: POZNAN Kraj: POLSKA Data wykonania operacji: 2025-10-09 02:00 Oryginalna kwota operacji: 6.00 Numer karty: 425125******0264 (6.00 PLN) | D16: 45941 | R16: kawa | S16: 129 | T16: Tytuł: 74838495269330672967710 Lokalizacja: Adres: ALL GOOD S.A. KAWIARNIA Miasto: WARSZAWA Kraj: POLSKA Data wykonania operacji: 2025-09-26 02:00 Oryginalna kwota operacji: 129.00 Numer karty: 425125******0264 (129.00 PLN) | U16: 45928
A17: biedronka | B17: 54.85 | C17: Tytuł: 000498849 74230785283177400441306 Lokalizacja: Adres: NETTO 5304 SCO K.3 Miasto: POZNAN Kraj: POLSKA Data wykonania operacji: 2025-10-09 02:00 Oryginalna kwota operacji: 54.85 Numer karty: 425125******0264 (54.85 PLN) | D17: 45941 | R17: żabka | S17: 7.49 | T17: Tytuł: 000498849 74230785269176550658733 Lokalizacja: Adres: ZABKA ZE578 K.2 Miasto: WARSZAWA Kraj: POLSKA Data wykonania operacji: 2025-09-26 02:00 Oryginalna kwota operacji: 7.49 Numer karty: 425125******0264 (7.49 PLN) | U17: 45928
A18: biedronka | B18: 23.18 | C18: Tytuł: 000498849 74230785283177398596624 Lokalizacja: Adres: NETTO 5304 SCO K.2 Miasto: POZNAN Kraj: POLSKA Data wykonania operacji: 2025-10-09 02:00 Oryginalna kwota operacji: 23.18 Numer karty: 425125******0264 (23.18 PLN) | D18: 45941 | R18: kawa | S18: 18 | T18: Tytuł: 74838495269330664839331 Lokalizacja: Adres: ALL GOOD S.A. KAWIARNIA Miasto: WARSZAWA Kraj: POLSKA Data wykonania operacji: 2025-09-26 02:00 Oryginalna kwota operacji: 18.00 Numer karty: 425125******0264 (18.00 PLN) | U18: 45928
A19: auto | B19: 73.67 | C19: Tytuł: 74988855281401316671161 Lokalizacja: Adres: JMIDF SP.Z.O.O.HEBE R052 Miasto: POZNAN Kraj: POLSKA Data wykonania operacji: 2025-10-08 02:00 Oryginalna kwota operacji: 73.67 Numer karty: 425125******0264 (73.67 PLN) | D19: 45940 | R19: fun | S19: 24 | T19: Tytuł: 74838495269330751459829 Lokalizacja: Adres: LOUVRE HOTELS GROUP 01 Miasto: Warszawa Kraj: POLSKA Data wykonania operacji: 2025-09-26 02:00 Oryginalna kwota operacji: 24.00 Numer karty: 425125******0264 (24.00 PLN) | U19: 45928
A20: rossman | B20: 16.97 | C20: Tytuł: 74838495282332376331253 Lokalizacja: Adres: ROSSMANN 11 Miasto: Poznan Kraj: POLSKA Data wykonania operacji: 2025-10-08 02:00 Oryginalna kwota operacji: 16.97 Numer karty: 425125******0264 (16.97 PLN) | D20: 45940 | R20: restauracje | S20: 32 | T20: Tytuł: 000498849 74230785269176569428417 Lokalizacja: Adres: TADIM DONER GRILL Miasto: WARSZAWA Kraj: POLSKA Data wykonania operacji: 2025-09-26 02:00 Oryginalna kwota operacji: 32.00 Numer karty: 425125******0264 (32.00 PLN) | U20: 45928
A21: fun | B21: 238 | C21: Tytuł: 000498707 74987075281033824464296 Lokalizacja: Adres: oleole.pl Miasto: Warszawa Kraj: POLSKA Data wykonania operacji: 2025-10-07 02:00 Oryginalna kwota operacji: 238.00 Numer karty: 425125******0264 (238.00 PLN) | D21: 45939 | R21: kawa | S21: 36 | T21: Tytuł: 74838495269330652892482 Lokalizacja: Adres: ALL GOOD S.A. KAWIARNIA Miasto: WARSZAWA Kraj: POLSKA Data wykonania operacji: 2025-09-26 02:00 Oryginalna kwota operacji: 36.00 Numer karty: 425125******0264 (36.00 PLN) | U21: 45928
... A46: auto | B46: 2239.72 | C46: BNP Paribas Leasing Services Sp. z o.o. 00-844 Warszawa, ul.Grzybowska 78 40050/10/2025/RL/L | D46: 45932 | R46: restauracje | S46: 94 | T46: Rachunek odbiorcy: 42 1090 1854 0000 0001 3287 4539 Nazwa odbiorcy: ODBIORCA PRZELEWU NA TELEFON Tytuł: PRZELEW NA TELEFON OD: 48796555364 DO: 487*****756 (94.00 PLN) | U46: 45917
R47: przejazdy | S47: 5 | T47: Nazwa odbiorcy: MOBILE-TRAFFIC-DATA SP. Z O. O. Adres odbiorcy: UL. DRUŻBICKIEGO 11 61-693 POZNAŃ Tytuł: ZAKUP BILETU KOMUNIKACYJNEGO W APLI KACJI IKO Referencje własne zleceniodawcy: 176079130729 (5.00 PLN) | U47: 45917
R48: żabka | S48: 10.99 | T48: Tytuł: 000498849 74230785258175820246603 Lokalizacja: Adres: ZABKA Z0685 K.1 Miasto: POZNAN Kraj: POLSKA Data wykonania operacji: 2025-09-15 02:00 Oryginalna kwota operacji: 10.99 Numer karty: 425125******0264 (10.99 PLN) | U48: 45917
R49: biedronka | S49: 73 | T49: Tytuł: 000498849 74230785257175765228195 Lokalizacja: Adres: STRONA Miasto: POZNAN Kraj: POLSKA Data wykonania operacji: 2025-09-14 02:00 Oryginalna kwota operacji: 73.00 Numer karty: 425125******0264 (73.00 PLN) | U49: 45916
R50: biedronka | S50: 5.5 | T50: Tytuł: 010061097 74169505257652570547420 Lokalizacja: Adres: FABRYKA FORMY POZNAN BALT Miasto: POZNAN Kraj: POLSKA Data wykonania operacji: 2025-09-14 02:00 Oryginalna kwota operacji: 5.50 Numer karty: 425125******0264 (5.50 PLN) | U50: 45916
R51: biuro | S51: 25 | T51: Tytuł: 00000090722718578 Numer telefonu: 48796555364 Lokalizacja: Adres: doladowania.t-mobile.pl 'Operacja: 00000090722718578 Numer referencyjny: 00000090722718578 (25.00 PLN) | U51: 45915
R52: kawa | S52: 41 | T52: Tytuł: 010046551 74230105256060365187268 Lokalizacja: Adres: ZIOMAL DARIA JEZEWSKA Miasto: POZNAN Kraj: POLSKA Data wykonania operacji: 2025-09-13 02:00 Oryginalna kwota operacji: 41.00 Numer karty: 425125******0264 (41.00 PLN) | U52: 45915
R53: auto | S53: 14.1 | T53: Tytuł: 000498849 74230785256175687558019 Lokalizacja: Adres: EKO LAND Miasto: POZNAN Kraj: POLSKA Data wykonania operacji: 2025-09-13 02:00 Oryginalna kwota operacji: 14.10 Numer karty: 425125******0264 (14.10 PLN) | U53: 45915
R54: apteka | S54: 43.98 | T54: Tytuł: 010061097 74169505256632566853538 Lokalizacja: Adres: APTEKA Miasto: POZNAN Kraj: POLSKA Data wykonania operacji: 2025-09-13 02:00 Oryginalna kwota operacji: 43.98 Numer karty: 425125******0264 (43.98 PLN) | U54: 45915
R55: auto | S55: 38 | T55: Tytuł: 74838495256328822897972 Lokalizacja: Adres: MARIETTA Miasto: POZNAN Kraj: POLSKA Data wykonania operacji: 2025-09-13 02:00 Oryginalna kwota operacji: 38.00 Numer karty: 425125******0264 (38.00 PLN) | U55: 45915
R56: kawa | S56: 220.99 | T56: Tytuł: 010087885 74987505256000707494044 Lokalizacja: Adres: BsCaffe Grzegorz Bienko Miasto: Stalowa Wola Kraj: POLSKA Data wykonania operacji: 2025-09-13 02:00 Oryginalna kwota operacji: 220.99 Numer karty: 425125******0264 (220.99 PLN) | U56: 45915
R57: auto | S57: 13.5 | T57: Tytuł: 010061097 74463675256622560965085 Lokalizacja: Adres: OKRUSZKI EWA PLANK Miasto: POZNAN Kraj: POLSKA Data wykonania operacji: 2025-09-13 02:00 Oryginalna kwota operacji: 13.50 Numer karty: 425125******0264 (13.50 PLN) | U57: 45915
R58: żabka | S58: 13.98 | T58: Tytuł: 000498849 74230785255175648069719 Lokalizacja: Adres: ZABKA Z0685 K.1 Miasto: POZNAN Kraj: POLSKA Data wykonania operacji: 2025-09-12 02:00 Oryginalna kwota operacji: 13.98 Numer karty: 425125******0264 (13.98 PLN) | U58: 45914
... R115: biuro | S115: 247.1 | T115: P4 Sp. z o.o. ul. Wynalazek 1 02-677 Warszawa F/10176247/09/25 | U115: 45904

Sheet wrzesien2025
E1: Przychody | H1: Stan konta na początku miesiąca | J1: Koszty stałe | K1: =SUM(J3:J991) -> 14488.75
A2: kategoria | B2: kwota | C2: opis | D2: data
A3: kawa | B3: 23.9 | C3: Tytuł: 74838495271331029792336 Lokalizacja: Adres: PL SBX POZNAN KAPONIERA Miasto: POZNAN Kraj: POLSKA Data wykonania operacji: 2025-09-28 02:00 Oryginalna kwota operacji: 23.90 Numer karty: 425125******0264 (23.90 PLN) | D3: 45930 | E3: sml | F3: 32914 | H3: =Zbiorczy!D63 -> 158860.84 | J3: =SUMIF($A$3:A$197, K3, B$3:B$197) -> 3213.25 | K3: zus | M3: =SUMIF($A$3:A$197, N3, B$3:B$197) -> 1001.99 | N3: biedronka | R3: kategoria | S3: kwota | T3: opis | U3: data
A4: kawa | B4: 36 | C4: Tytuł: 74838495271330989542053 Lokalizacja: Adres: AGRAWKA Miasto: POZNAN Kraj: POLSKA Data wykonania operacji: 2025-09-28 02:00 Oryginalna kwota operacji: 36.00 Numer karty: 425125******0264 (36.00 PLN) | D4: 45930 | E4: skąd? | J4: =SUMIF($A$3:A$197, K4, B$3:B$197) -> 3280 | K4: PIT36 | M4: =SUMIF($A$3:A$197, N4, B$3:B$197) -> 115.81 | N4: żabka | R4: kawa | S4: 23.9 | T4: Tytuł: 74838495271331029792336 Lokalizacja: Adres: PL SBX POZNAN KAPONIERA Miasto: POZNAN Kraj: POLSKA Data wykonania operacji: 2025-09-28 02:00 Oryginalna kwota operacji: 23.90 Numer karty: 425125******0264 (23.90 PLN) | U4: 45930
A5: mieszkanie | B5: 320 | C5: Rachunek odbiorcy: 73 1090 2372 0000 0001 1332 9442 Nazwa odbiorcy: MARTA SZCZYGIEŁ Tytuł: PRZELEW NA TELEFON OD: 48796555364 DO: 486*****967 (320.00 PLN) | D5: 45929 | E5: sml prezent | J5: =SUMIF($A$3:A$197, K5, B$3:B$197) -> 5619 | K5: VAT | M5: =SUMIF($A$3:A$197, N5, B$3:B$197) -> 3462.84 | N5: auto | R5: kawa | S5: 36 | T5: Tytuł: 74838495271330989542053 Lokalizacja: Adres: AGRAWKA Miasto: POZNAN Kraj: POLSKA Data wykonania operacji: 2025-09-28 02:00 Oryginalna kwota operacji: 36.00 Numer karty: 425125******0264 (36.00 PLN) | U5: 45930
A6: przejazdy | B6: 5 | C6: Nazwa odbiorcy: MOBILE-TRAFFIC-DATA SP. Z O. O. Adres odbiorcy: UL. DRUŻBICKIEGO 11 61-693 POZNAŃ Tytuł: ZAKUP BILETU KOMUNIKACYJNEGO W APLI KACJI IKO Referencje własne zleceniodawcy: 176117332131 (5.00 PLN) | D6: 45929 | J6: =SUMIF($A$3:A$197, K6, B$3:B$197) -> 2376.5 | K6: mieszkanie | M6: =SUMIF($A$3:A$197, N6, B$3:B$197) -> 897.91 | N6: paliwo | R6: mieszkanie | S6: 320 | T6: Rachunek odbiorcy: 73 1090 2372 0000 0001 1332 9442 Nazwa odbiorcy: MARTA SZCZYGIEŁ Tytuł: PRZELEW NA TELEFON OD: 48796555364 DO: 486*****967 (320.00 PLN) | U6: 45929
A7: przejazdy | B7: 5 | C7: Nazwa odbiorcy: MOBILE-TRAFFIC-DATA SP. Z O. O. Adres odbiorcy: UL. DRUŻBICKIEGO 11 61-693 POZNAŃ Tytuł: ZAKUP BILETU KOMUNIKACYJNEGO W APLI KACJI IKO Referencje własne zleceniodawcy: 176117028129 (5.00 PLN) | D7: 45929 | J7: =SUMIF($A$3:A$197, K7, B$3:B$197) -> 0 | K7: kredyt | M7: =SUMIF($A$3:A$197, N7, B$3:B$197) -> 3594.59 | N7: fun | R7: przejazdy | S7: 5 | T7: Nazwa odbiorcy: MOBILE-TRAFFIC-DATA SP. Z O. O. Adres odbiorcy: UL. DRUŻBICKIEGO 11 61-693 POZNAŃ Tytuł: ZAKUP BILETU KOMUNIKACYJNEGO W APLI KACJI IKO Referencje własne zleceniodawcy: 176117332131 (5.00 PLN) | U7: 45929
A8: restauracje | B8: 33 | C8: Tytuł: 010046551 74230105270060695629718 Lokalizacja: Adres: PATILA DONER KEBAP Miasto: WARSZAWA Kraj: POLSKA Data wykonania operacji: 2025-09-27 02:00 Oryginalna kwota operacji: 33.00 Numer karty: 425125******0264 (33.00 PLN) | D8: 45929 | M8: =SUMIF($A$3:A$197, N8, B$3:B$197) -> 3462.84 | N8: auto | R8: przejazdy | S8: 5 | T8: Nazwa odbiorcy: MOBILE-TRAFFIC-DATA SP. Z O. O. Adres odbiorcy: UL. DRUŻBICKIEGO 11 61-693 POZNAŃ Tytuł: ZAKUP BILETU KOMUNIKACYJNEGO W APLI KACJI IKO Referencje własne zleceniodawcy: 176117028129 (5.00 PLN) | U8: 45929
A9: kawa | B9: 22 | C9: Tytuł: 74838495270330831227797 Lokalizacja: Adres: ALL GOOD S.A. KAWIARNIA Miasto: WARSZAWA Kraj: POLSKA Data wykonania operacji: 2025-09-27 02:00 Oryginalna kwota operacji: 22.00 Numer karty: 425125******0264 (22.00 PLN) | D9: 45929 | M9: =SUMIF($A$3:A$197, N9, B$3:B$197) -> 324.56 | N9: restauracje | R9: restauracje | S9: 33 | T9: Tytuł: 010046551 74230105270060695629718 Lokalizacja: Adres: PATILA DONER KEBAP Miasto: WARSZAWA Kraj: POLSKA Data wykonania operacji: 2025-09-27 02:00 Oryginalna kwota operacji: 33.00 Numer karty: 425125******0264 (33.00 PLN) | U9: 45929
A10: biedronka | B10: 59.98 | C10: Tytuł: 74838495270330948540132 Lokalizacja: Adres: ME M03 02 Miasto: POZNAN Kraj: POLSKA Data wykonania operacji: 2025-09-27 02:00 Oryginalna kwota operacji: 59.98 Numer karty: 425125******0264 (59.98 PLN) | D10: 45929 | R10: kawa | S10: 22 | T10: Tytuł: 74838495270330831227797 Lokalizacja: Adres: ALL GOOD S.A. KAWIARNIA Miasto: WARSZAWA Kraj: POLSKA Data wykonania operacji: 2025-09-27 02:00 Oryginalna kwota operacji: 22.00 Numer karty: 425125******0264 (22.00 PLN) | U10: 45929
A11: biedronka | B11: 376.72 | C11: Tytuł: 74838495271330946294426 Lokalizacja: Adres: LIDL GLOGOWSKA Miasto: Poznan Kraj: POLSKA Data wykonania operacji: 2025-09-27 02:00 Oryginalna kwota operacji: 376.72 Numer karty: 425125******0264 (376.72 PLN) | D11: 45929 | R11: biedronka | S11: 59.98 | T11: Tytuł: 74838495270330948540132 Lokalizacja: Adres: ME M03 02 Miasto: POZNAN Kraj: POLSKA Data wykonania operacji: 2025-09-27 02:00 Oryginalna kwota operacji: 59.98 Numer karty: 425125******0264 (59.98 PLN) | U11: 45929
A12: kawa | B12: 51 | C12: Tytuł: 74838495270330817887705 Lokalizacja: Adres: ALL GOOD S.A. KAWIARNIA Miasto: WARSZAWA Kraj: POLSKA Data wykonania operacji: 2025-09-27 02:00 Oryginalna kwota operacji: 51.00 Numer karty: 425125******0264 (51.00 PLN) | D12: 45929 | R12: biedronka | S12: 376.72 | T12: Tytuł: 74838495271330946294426 Lokalizacja: Adres: LIDL GLOGOWSKA Miasto: Poznan Kraj: POLSKA Data wykonania operacji: 2025-09-27 02:00 Oryginalna kwota operacji: 376.72 Numer karty: 425125******0264 (376.72 PLN) | U12: 45929
A13: auto | B13: 4.5 | C13: Tytuł: 74810315270171203357685 Lokalizacja: Adres: WARS Automat vendingowy Miasto: Warszawa Kraj: POLSKA Data wykonania operacji: 2025-09-27 02:00 Oryginalna kwota operacji: 4.50 Numer karty: 425125******0264 (4.50 PLN) | D13: 45929 | R13: kawa | S13: 51 | T13: Tytuł: 74838495270330817887705 Lokalizacja: Adres: ALL GOOD S.A. KAWIARNIA Miasto: WARSZAWA Kraj: POLSKA Data wykonania operacji: 2025-09-27 02:00 Oryginalna kwota operacji: 51.00 Numer karty: 425125******0264 (51.00 PLN) | U13: 45929
A14: auto | B14: 4.5 | C14: Tytuł: 74810315270171203487599 Lokalizacja: Adres: WARS Automat vendingowy Miasto: Warszawa Kraj: POLSKA Data wykonania operacji: 2025-09-27 02:00 Oryginalna kwota operacji: 4.50 Numer karty: 425125******0264 (4.50 PLN) | D14: 45929 | R14: auto | S14: 4.5 | T14: Tytuł: 74810315270171203357685 Lokalizacja: Adres: WARS Automat vendingowy Miasto: Warszawa Kraj: POLSKA Data wykonania operacji: 2025-09-27 02:00 Oryginalna kwota operacji: 4.50 Numer karty: 425125******0264 (4.50 PLN) | U14: 45929
A15: kawa | B15: 129 | C15: Tytuł: 74838495269330672967710 Lokalizacja: Adres: ALL GOOD S.A. KAWIARNIA Miasto: WARSZAWA Kraj: POLSKA Data wykonania operacji: 2025-09-26 02:00 Oryginalna kwota operacji: 129.00 Numer karty: 425125******0264 (129.00 PLN) | D15: 45928 | R15: auto | S15: 4.5 | T15: Tytuł: 74810315270171203487599 Lokalizacja: Adres: WARS Automat vendingowy Miasto: Warszawa Kraj: POLSKA Data wykonania operacji: 2025-09-27 02:00 Oryginalna kwota operacji: 4.50 Numer karty: 425125******0264 (4.50 PLN) | U15: 45929
A16: żabka | B16: 7.49 | C16: Tytuł: 000498849 74230785269176550658733 Lokalizacja: Adres: ZABKA ZE578 K.2 Miasto: WARSZAWA Kraj: POLSKA Data wykonania operacji: 2025-09-26 02:00 Oryginalna kwota operacji: 7.49 Numer karty: 425125******0264 (7.49 PLN) | D16: 45928 | R16: kawa | S16: 129 | T16: Tytuł: 74838495269330672967710 Lokalizacja: Adres: ALL GOOD S.A. KAWIARNIA Miasto: WARSZAWA Kraj: POLSKA Data wykonania operacji: 2025-09-26 02:00 Oryginalna kwota operacji: 129.00 Numer karty: 425125******0264 (129.00 PLN) | U16: 45928
A17: kawa | B17: 18 | C17: Tytuł: 74838495269330664839331 Lokalizacja: Adres: ALL GOOD S.A. KAWIARNIA Miasto: WARSZAWA Kraj: POLSKA Data wykonania operacji: 2025-09-26 02:00 Oryginalna kwota operacji: 18.00 Numer karty: 425125******0264 (18.00 PLN) | D17: 45928 | R17: żabka | S17: 7.49 | T17: Tytuł: 000498849 74230785269176550658733 Lokalizacja: Adres: ZABKA ZE578 K.2 Miasto: WARSZAWA Kraj: POLSKA Data wykonania operacji: 2025-09-26 02:00 Oryginalna kwota operacji: 7.49 Numer karty: 425125******0264 (7.49 PLN) | U17: 45928
A18: fun | B18: 24 | C18: Tytuł: 74838495269330751459829 Lokalizacja: Adres: LOUVRE HOTELS GROUP 01 Miasto: Warszawa Kraj: POLSKA Data wykonania operacji: 2025-09-26 02:00 Oryginalna kwota operacji: 24.00 Numer karty: 425125******0264 (24.00 PLN) | D18: 45928 | R18: kawa | S18: 18 | T18: Tytuł: 74838495269330664839331 Lokalizacja: Adres: ALL GOOD S.A. KAWIARNIA Miasto: WARSZAWA Kraj: POLSKA Data wykonania operacji: 2025-09-26 02:00 Oryginalna kwota operacji: 18.00 Numer karty: 425125******0264 (18.00 PLN) | U18: 45928
A19: restauracje | B19: 32 | C19: Tytuł: 000498849 74230785269176569428417 Lokalizacja: Adres: TADIM DONER GRILL Miasto: WARSZAWA Kraj: POLSKA Data wykonania operacji: 2025-09-26 02:00 Oryginalna kwota operacji: 32.00 Numer karty: 425125******0264 (32.00 PLN) | D19: 45928 | R19: fun | S19: 24 | T19: Tytuł: 74838495269330751459829 Lokalizacja: Adres: LOUVRE HOTELS GROUP 01 Miasto: Warszawa Kraj: POLSKA Data wykonania operacji: 2025-09-26 02:00 Oryginalna kwota operacji: 24.00 Numer karty: 425125******0264 (24.00 PLN) | U19: 45928
A20: kawa | B20: 36 | C20: Tytuł: 74838495269330652892482 Lokalizacja: Adres: ALL GOOD S.A. KAWIARNIA Miasto: WARSZAWA Kraj: POLSKA Data wykonania operacji: 2025-09-26 02:00 Oryginalna kwota operacji: 36.00 Numer karty: 425125******0264 (36.00 PLN) | D20: 45928 | R20: restauracje | S20: 32 | T20: Tytuł: 000498849 74230785269176569428417 Lokalizacja: Adres: TADIM DONER GRILL Miasto: WARSZAWA Kraj: POLSKA Data wykonania operacji: 2025-09-26 02:00 Oryginalna kwota operacji: 32.00 Numer karty: 425125******0264 (32.00 PLN) | U20: 45928
A21: rossman | B21: 17.48 | C21: Tytuł: 74838495270330724922751 Lokalizacja: Adres: ROSSMANN 134 Miasto: WARSZAWA Kraj: POLSKA Data wykonania operacji: 2025-09-26 02:00 Oryginalna kwota operacji: 17.48 Numer karty: 425125******0264 (17.48 PLN) | D21: 45928 | R21: kawa | S21: 36 | T21: Tytuł: 74838495269330652892482 Lokalizacja: Adres: ALL GOOD S.A. KAWIARNIA Miasto: WARSZAWA Kraj: POLSKA Data wykonania operacji: 2025-09-26 02:00 Oryginalna kwota operacji: 36.00 Numer karty: 425125******0264 (36.00 PLN) | U21: 45928
... A114: biuro | B114: 247.1 | C114: P4 Sp. z o.o. ul. Wynalazek 1 02-677 Warszawa F/10176247/09/25 | D114: 45904 | R114: biuro | S114: 82.29 | T114: Orange Polska S.A. Aleje Jerozolimskie 160 02-326 Warszawa NIP 526-025-09-95 F0083222849/009/25 | U114: 45904
R115: biuro | S115: 247.1 | T115: P4 Sp. z o.o. ul. Wynalazek 1 02-677 Warszawa F/10176247/09/25 | U115: 45904

Sheet sierpien2025
E1: Przychody | H1: Stan konta na początku miesiąca | J1: Koszty stałe | K1: =SUM(J3:J991) -> 15100.75
A2: kategoria | B2: kwota | C2: opis | D2: data
E3: sml | F3: 29999 | H3: =Zbiorczy!D62 -> 158908.08 | J3: =SUMIF($A$3:A$197, K3, B$3:B$197) -> 3213.25 | K3: zus | M3: =SUMIF($A$3:A$197, N3, B$3:B$197) -> 278.61 | N3: biedronka
A4: auto | B4: 17.6 | C4: Nazwa odbiorcy: PKO BP FINAT SP. Z O.O. Adres odbiorcy: UL. CHMIELNA 89 00-805 WARSZAWA Tytuł: OPŁ. ZA PRZEJAZD A1, PPO RUSOCIN - SPO NOWE MARZY, NR TRANS. 7247481, 2025-08-31 (17.60 PLN) | D4: 45900 | E4: skąd? | F4: 468 | J4: =SUMIF($A$3:A$197, K4, B$3:B$197) -> 3185 | K4: PIT36 | M4: =SUMIF($A$3:A$197, N4, B$3:B$197) -> 67.64 | N4: żabka
A5: restauracje | B5: 33.3 | C5: Tytuł: 74838495242326520637648 Lokalizacja: Adres: MCDONALDS Miasto: ZNIN Kraj: POLSKA Data wykonania operacji: 2025-08-29 02:00 Oryginalna kwota operacji: 33.30 Numer karty: 425125******0264 (33.30 PLN) | D5: 45900 | E5: sml prezent | J5: =SUMIF($A$3:A$197, K5, B$3:B$197) -> 5176 | K5: VAT | M5: =SUMIF($A$3:A$197, N5, B$3:B$197) -> 3091.23 | N5: auto
A6: biedronka | B6: 4.5 | C6: Tytuł: 010061097 74169505240642405692236 Lokalizacja: Adres: FABRYKA FORMY POZNAN BALT Miasto: POZNAN Kraj: POLSKA Data wykonania operacji: 2025-08-28 02:00 Oryginalna kwota operacji: 4.50 Numer karty: 425125******0264 (4.50 PLN) | D6: 45899 | J6: =SUMIF($A$3:A$197, K6, B$3:B$197) -> 3526.5 | K6: mieszkanie | M6: =SUMIF($A$3:A$197, N6, B$3:B$197) -> 1187.08 | N6: paliwo
A7: paliwo | B7: 17.6 | C7: Nazwa odbiorcy: PKO BP FINAT SP. Z O.O. Adres odbiorcy: UL. CHMIELNA 89 00-805 WARSZAWA Tytuł: OPŁ. ZA PRZEJAZD A1, SPO NOWE MARZY - PPO RUSOCIN, NR TRANS. 7234794, 2025-08-29 (17.60 PLN) | D7: 45898 | J7: =SUMIF($A$3:A$197, K7, B$3:B$197) -> 0 | K7: kredyt | M7: =SUMIF($A$3:A$197, N7, B$3:B$197) -> 4324.52 | N7: fun
A8: mieszkanie | B8: 1330 | C8: Tytuł: 010085232 74350275240011302158361 Lokalizacja: Adres: Revolut**7108* Miasto: Dublin Kraj: IRLANDIA Data wykonania operacji: 2025-08-28 02:00 Oryginalna kwota operacji: 1330.00 Numer karty: 425125******0264 (1330.00 PLN) | D8: 45898 | M8: =SUMIF($A$3:A$197, N8, B$3:B$197) -> 3091.23 | N8: auto
A9: żabka | B9: 2.99 | C9: Tytuł: 000498849 74230785238174464778646 Lokalizacja: Adres: ZABKA Z0685 K.1 Miasto: POZNAN Kraj: POLSKA Data wykonania operacji: 2025-08-26 02:00 Oryginalna kwota operacji: 2.99 Numer karty: 425125******0264 (2.99 PLN) | D9: 45897 | M9: =SUMIF($A$3:A$197, N9, B$3:B$197) -> 55.3 | N9: restauracje
A10: biedronka | B10: 43.93 | C10: Tytuł: 000498849 74230785239174504801431 Lokalizacja: Adres: NETTO 5304 SCO K.3 Miasto: POZNAN Kraj: POLSKA Data wykonania operacji: 2025-08-26 02:00 Oryginalna kwota operacji: 43.93 Numer karty: 425125******0264 (43.93 PLN) | D10: 45897
A11: apteka | B11: 25.49 | C11: Tytuł: 74838495237325811450841 Lokalizacja: Adres: ZIKO APTEKA 05 Miasto: Poznan Kraj: POLSKA Data wykonania operacji: 2025-08-25 02:00 Oryginalna kwota operacji: 25.49 Numer karty: 425125******0264 (25.49 PLN) | D11: 45896
A12: lekarz | B12: 250 | C12: Tytuł: 010061097 74169505237622371858909 Lokalizacja: Adres: PRACOWNIA PSYCHOLOGICZNA Miasto: POZNAN Kraj: POLSKA Data wykonania operacji: 2025-08-25 02:00 Oryginalna kwota operacji: 250.00 Numer karty: 425125******0264 (250.00 PLN) | D12: 45896
A13: mieszkanie | B13: 450 | C13: Rachunek odbiorcy: 73 1090 2372 0000 0001 1332 9442 Nazwa odbiorcy: MARTA SZCZYGIEŁ Tytuł: PRZELEW NA TELEFON OD: 48796555364 DO: 486*****967 (450.00 PLN) | D13: 45895
A14: żabka | B14: 19.98 | C14: Tytuł: 000498849 74230785236174338351234 Lokalizacja: Adres: ZABKA ZA319 K.1 Miasto: ZABKOWICE SLA Kraj: POLSKA Data wykonania operacji: 2025-08-24 02:00 Oryginalna kwota operacji: 19.98 Numer karty: 425125******0264 (19.98 PLN) | D14: 45895
A15: paliwo | B15: 12 | C15: Tytuł: 74838495237325767042980 Lokalizacja: Adres: ORLEN STACJA NR 4497 Miasto: WISZNIA MALA Kraj: POLSKA Data wykonania operacji: 2025-08-24 02:00 Oryginalna kwota operacji: 12.00 Numer karty: 425125******0264 (12.00 PLN) | D15: 45895
A16: krypto | B16: 257 | C16: Tytuł: 010085232 74350275236011256854938 Lokalizacja: Adres: Revolut**7108* Miasto: Dublin Kraj: IRLANDIA Data wykonania operacji: 2025-08-24 02:00 Oryginalna kwota operacji: 257.00 Numer karty: 425125******0264 (257.00 PLN) | D16: 45895
A17: przejazdy | B17: 4 | C17: Nazwa odbiorcy: MOBILE-TRAFFIC-DATA SP. Z O. O. Adres odbiorcy: UL. DRUŻBICKIEGO 11 61-693 POZNAŃ Tytuł: ZAKUP BILETU KOMUNIKACYJNEGO W APLI KACJI IKO Referencje własne zleceniodawcy: 175993463979 (4.00 PLN) | D17: 45894
A18: przejazdy | B18: 4 | C18: Nazwa odbiorcy: MOBILE-TRAFFIC-DATA SP. Z O. O. Adres odbiorcy: UL. DRUŻBICKIEGO 11 61-693 POZNAŃ Tytuł: ZAKUP BILETU KOMUNIKACYJNEGO W APLI KACJI IKO Referencje własne zleceniodawcy: 175993238556 (4.00 PLN) | D18: 45894
A19: fun | B19: 38 | C19: Tytuł: 74410495235026071281722 Lokalizacja: Adres: Klubokawiarnia Kl33384 Miasto: Gliwice Kraj: POLSKA Data wykonania operacji: 2025-08-23 02:00 Oryginalna kwota operacji: 38.00 Numer karty: 425125******0264 (38.00 PLN) | D19: 45894
A20: PIT36 | B20: 5 | C20: Tytuł: 010061097 74463675235592353807396 Lokalizacja: Adres: MYJNIA SZPITALNA KNUROW Miasto: KNUROW Kraj: POLSKA Data wykonania operacji: 2025-08-22 02:00 Oryginalna kwota operacji: 5.00 Numer karty: 425125******0264 (5.00 PLN) | D20: 45894
A21: PIT36 | B21: 5 | C21: Tytuł: 010061097 74463675235592353804807 Lokalizacja: Adres: MYJNIA SZPITALNA KNUROW Miasto: KNUROW Kraj: POLSKA Data wykonania operacji: 2025-08-22 02:00 Oryginalna kwota operacji: 5.00 Numer karty: 425125******0264 (5.00 PLN) | D21: 45894
... A95: paliwo | B95: 206.44 | C95: ORLEN STACJA NR 422 POZNAN POL Płatność kartą 02.08.2025 Nr karty 4598xx4778 | D95: 45871

Sheet lipiec2025
E1: Przychody | H1: Stan konta na początku miesiąca | J1: Koszty stałe | K1: =SUM(J3:J991) -> 13925.74
A2: kategoria | B2: kwota | C2: opis | D2: data
A3: biedronka | B3: 35.08 | C3: Tytuł: 000498849 74230785207172297666647 Lokalizacja: Adres: NETTO 5304 SCO K.2 Miasto: POZNAN Kraj: POLSKA Data wykonania operacji: 2025-07-25 02:00 Oryginalna kwota operacji: 35.08 Numer karty: 425125******0264 (35.08 PLN) | D3: 45865 | E3: sml | F3: 32545 | H3: =Zbiorczy!D61 -> 160100.21 | J3: =SUMIF($A$3:A$197, K3, B$3:B$197) -> 3213.25 | K3: zus | M3: =SUMIF($A$3:A$197, N3, B$3:B$197) -> 206.28 | N3: biedronka
A4: biedronka | B4: 4.5 | C4: Tytuł: 010061097 74169505206652065173361 Lokalizacja: Adres: FABRYKA FORMY POZNAN BALT Miasto: POZNAN Kraj: POLSKA Data wykonania operacji: 2025-07-25 02:00 Oryginalna kwota operacji: 4.50 Numer karty: 425125******0264 (4.50 PLN) | D4: 45865 | E4: skąd? | F4: 1990 | J4: =SUMIF($A$3:A$197, K4, B$3:B$197) -> 3781 | K4: PIT36 | M4: =SUMIF($A$3:A$197, N4, B$3:B$197) -> 80.77 | N4: żabka
A5: fun | B5: 500 | C5: Tytuł: 010085232 74350275205010817772842 Lokalizacja: Adres: Revolut**7108* Miasto: Dublin Kraj: IRLANDIA Data wykonania operacji: 2025-07-24 02:00 Oryginalna kwota operacji: 500.00 Numer karty: 425125******0264 (500.00 PLN) | D5: 45864 | E5: sml prezent | J5: =SUMIF($A$3:A$197, K5, B$3:B$197) -> 5730 | K5: VAT | M5: =SUMIF($A$3:A$197, N5, B$3:B$197) -> 4777.93 | N5: auto
A6: restauracje | B6: 22 | C6: Tytuł: 000498849 74230785204172102030230 Lokalizacja: Adres: SOUP CULTURE ROSWELL Miasto: POZNAN Kraj: POLSKA Data wykonania operacji: 2025-07-23 02:00 Oryginalna kwota operacji: 22.00 Numer karty: 425125******0264 (22.00 PLN) | D6: 45863 | J6: =SUMIF($A$3:A$197, K6, B$3:B$197) -> 1201.49 | K6: mieszkanie | M6: =SUMIF($A$3:A$197, N6, B$3:B$197) -> 239.12 | N6: paliwo
A7: ubrania | B7: 1199.98 | C7: Tytuł: 00000089650281362 Numer telefonu: 48796555364 Lokalizacja: Adres: www.zalando.pl 'Operacja: 00000089650281362 Numer referencyjny: 00000089650281362 (1199.98 PLN) | D7: 45862 | J7: =SUMIF($A$3:A$197, K7, B$3:B$197) -> 0 | K7: kredyt | M7: =SUMIF($A$3:A$197, N7, B$3:B$197) -> 11277.03 | N7: fun
A8: fun | B8: 77.86 | C8: Tytuł: 010072805 24871155203106473917290 Lokalizacja: Adres: ALIEXPRESS.COM Miasto: Luxembourg Kraj: LUKSEMBURG Data wykonania operacji: 2025-07-22 02:00 Oryginalna kwota operacji: 77.86 Numer karty: 425125******0264 (77.86 PLN) | D8: 45862 | M8: =SUMIF($A$3:A$197, N8, B$3:B$197) -> 4777.93 | N8: auto
A9: biedronka | B9: 4.5 | C9: Tytuł: 010061097 74169505203642030729077 Lokalizacja: Adres: FABRYKA FORMY POZNAN BALT Miasto: POZNAN Kraj: POLSKA Data wykonania operacji: 2025-07-22 02:00 Oryginalna kwota operacji: 4.50 Numer karty: 425125******0264 (4.50 PLN) | D9: 45862 | M9: =SUMIF($A$3:A$197, N9, B$3:B$197) -> 888.52 | N9: restauracje
A10: restauracje | B10: 20 | C10: Tytuł: 000498849 74230785203172053212739 Lokalizacja: Adres: STRONA Miasto: POZNAN Kraj: POLSKA Data wykonania operacji: 2025-07-22 02:00 Oryginalna kwota operacji: 20.00 Numer karty: 425125******0264 (20.00 PLN) | D10: 45862
A11: biuro | B11: 39.99 | C11: Tytuł: 010066928 74056285203100586281006 Lokalizacja: Adres: APPLE.COM/BILL Miasto: APPLE.COM/BIL Kraj: IRLANDIA Data wykonania operacji: 2025-07-22 02:00 Oryginalna kwota operacji: 39.99 Numer karty: 425125******0264 (39.99 PLN) | D11: 45862
A12: mieszkanie | B12: 235 | C12: Rachunek odbiorcy: 73 1090 2372 0000 0001 1332 9442 Nazwa odbiorcy: MARTA SZCZYGIEŁ Tytuł: PRZELEW NA TELEFON OD: 48796555364 DO: 486*****967 (235.00 PLN) | D12: 45860
A13: lekarz | B13: 250 | C13: Rachunek odbiorcy: 25 1140 2004 0000 3102 7803 3777 Nazwa odbiorcy: KAMIL WIETESKA Tytuł: OLAF KRZWCZYK 21.07.2025 Referencje własne zleceniodawcy: 175875884623 (250.00 PLN) | D13: 45859
A14: żabka | B14: 19.49 | C14: Tytuł: 000498849 74230785200171847484920 Lokalizacja: Adres: ZABKA Z4067 K.2 Miasto: WROCLAW Kraj: POLSKA Data wykonania operacji: 2025-07-19 02:00 Oryginalna kwota operacji: 19.49 Numer karty: 425125******0264 (19.49 PLN) | D14: 45859
A15: kawa | B15: 15.3 | C15: Tytuł: 74838495200320058215273 Lokalizacja: Adres: LARKS Miasto: WROCLAW Kraj: POLSKA Data wykonania operacji: 2025-07-19 02:00 Oryginalna kwota operacji: 15.30 Numer karty: 425125******0264 (15.30 PLN) | D15: 45859
A16: kawa | B16: 15.3 | C16: Tytuł: 74838495199319881980171 Lokalizacja: Adres: LARKS Miasto: WROCLAW Kraj: POLSKA Data wykonania operacji: 2025-07-18 02:00 Oryginalna kwota operacji: 15.30 Numer karty: 425125******0264 (15.30 PLN) | D16: 45858
A17: apteka | B17: 59.98 | C17: Tytuł: 74838495199319887804557 Lokalizacja: Adres: Ziko Apteka Miasto: Wroclaw Kraj: POLSKA Data wykonania operacji: 2025-07-18 02:00 Oryginalna kwota operacji: 59.98 Numer karty: 425125******0264 (59.98 PLN) | D17: 45858
A18: kawa | B18: 15.25 | C18: Tytuł: 74810315199163967373238 Lokalizacja: Adres: CAFE ROZRUSZNIK Miasto: WROCLAW Kraj: POLSKA Data wykonania operacji: 2025-07-18 02:00 Oryginalna kwota operacji: 15.25 Numer karty: 425125******0264 (15.25 PLN) | D18: 45858
A19: żabka | B19: 10.1 | C19: Tytuł: 000498849 74230785199171751038186 Lokalizacja: Adres: ZABKA ZC250 K.2 Miasto: WROCLAW Kraj: POLSKA Data wykonania operacji: 2025-07-18 02:00 Oryginalna kwota operacji: 10.10 Numer karty: 425125******0264 (10.10 PLN) | D19: 45858
A20: fun | B20: 5 | C20: Tytuł: 74810315199163929109423 Lokalizacja: Adres: KWATERA GLOWNA Miasto: WROCLAW Kraj: POLSKA Data wykonania operacji: 2025-07-18 02:00 Oryginalna kwota operacji: 5.00 Numer karty: 425125******0264 (5.00 PLN) | D20: 45858
A21: rossman | B21: 87.49 | C21: Tytuł: 74988855199401249230383 Lokalizacja: Adres: JMIDF SP.Z.O.O.HEBE R147 Miasto: WROCLAW Kraj: POLSKA Data wykonania operacji: 2025-07-18 02:00 Oryginalna kwota operacji: 87.49 Numer karty: 425125******0264 (87.49 PLN) | D21: 45858
... A105: biedronka | B105: 4.5 | C105: Tytuł: 010061097 74169505206652065173361 Lokalizacja: Adres: FABRYKA FORMY POZNAN BALT Miasto: POZNAN Kraj: POLSKA Data wykonania operacji: 2025-07-25 02:00 Oryginalna kwota operacji: 4.50 Numer karty: 425125******0264 (4.50 PLN) | D105: 45865

Sheet czerwiec2025
E1: Przychody | H1: Stan konta na początku miesiąca | J1: Koszty stałe | K1: =SUM(J3:J991) -> 15940.71
A2: kategoria | B2: kwota | C2: opis | D2: data
A3: biuro | B3: 5 | C3: Tytuł: 00000089135103356 Numer telefonu: 48796555364 Lokalizacja: Adres: doladuj.plus.pl 'Operacja: 00000089135103356 Numer referencyjny: 00000089135103356 (5.00 PLN) | D3: 45838 | E3: sml | F3: 35649 | H3: =Zbiorczy!D60 -> 151881.83 | J3: =SUMIF($A$3:A$197, K3, B$3:B$197) -> 3213.25 | K3: zus | M3: =SUMIF($A$3:A$197, N3, B$3:B$197) -> 978.15 | N3: biedronka
A4: biedronka | B4: 6 | C4: Tytuł: 74838495179316725552566 Lokalizacja: Adres: STARE TBILISI YANA OLIU Miasto: POZNAN Kraj: POLSKA Data wykonania operacji: 2025-06-28 02:00 Oryginalna kwota operacji: 6.00 Numer karty: 425125******0264 (6.00 PLN) | D4: 45838 | E4: skąd? | J4: =SUMIF($A$3:A$197, K4, B$3:B$197) -> 3893 | K4: PIT36 | M4: =SUMIF($A$3:A$197, N4, B$3:B$197) -> 79.66 | N4: żabka
A5: biedronka | B5: 91.09 | C5: Tytuł: 74838495180316723024821 Lokalizacja: Adres: LIDL MATYI Miasto: POZNAN Kraj: POLSKA Data wykonania operacji: 2025-06-28 02:00 Oryginalna kwota operacji: 91.09 Numer karty: 425125******0264 (91.09 PLN) | D5: 45838 | E5: sml prezent | J5: =SUMIF($A$3:A$197, K5, B$3:B$197) -> 6306 | K5: VAT | M5: =SUMIF($A$3:A$197, N5, B$3:B$197) -> 2422.49 | N5: auto
A6: biedronka | B6: 41.31 | C6: Tytuł: 000498849 74230785180170428022871 Lokalizacja: Adres: NETTO 5304 SCO K.2 Miasto: POZNAN Kraj: POLSKA Data wykonania operacji: 2025-06-28 02:00 Oryginalna kwota operacji: 41.31 Numer karty: 425125******0264 (41.31 PLN) | D6: 45838 | J6: =SUMIF($A$3:A$197, K6, B$3:B$197) -> 2528.46 | K6: mieszkanie | M6: =SUMIF($A$3:A$197, N6, B$3:B$197) -> 839.82 | N6: paliwo
A7: restauracje | B7: 70 | C7: Tytuł: 74838495178316629756108 Lokalizacja: Adres: UKI UKI Miasto: WARSZAWA Kraj: POLSKA Data wykonania operacji: 2025-06-27 02:00 Oryginalna kwota operacji: 70.00 Numer karty: 425125******0264 (70.00 PLN) | D7: 45837 | J7: =SUMIF($A$3:A$197, K7, B$3:B$197) -> 0 | K7: kredyt | M7: =SUMIF($A$3:A$197, N7, B$3:B$197) -> 2389.14 | N7: fun
A8: restauracje | B8: 19 | C8: Tytuł: 74410495178025297766952 Lokalizacja: Adres: Foka Mochi 56748 Miasto: WARSZAWA Kraj: POLSKA Data wykonania operacji: 2025-06-27 02:00 Oryginalna kwota operacji: 19.00 Numer karty: 425125******0264 (19.00 PLN) | D8: 45837 | M8: =SUMIF($A$3:A$197, N8, B$3:B$197) -> 2422.49 | N8: auto
A9: przejazdy | B9: 149 | C9: Tytuł: 010061097 74463675178501791766337 Lokalizacja: Adres: WWW BILKOM PL Miasto: WARSZAWA Kraj: POLSKA Data wykonania operacji: 2025-06-27 02:00 Oryginalna kwota operacji: 149.00 Numer karty: 425125******0264 (149.00 PLN) | D9: 45837 | M9: =SUMIF($A$3:A$197, N9, B$3:B$197) -> 1009.29 | N9: restauracje
A10: żabka | B10: 4.5 | C10: Tytuł: 000498849 74230785178170314281692 Lokalizacja: Adres: ZABKA Z0685 K.1 Miasto: POZNAN Kraj: POLSKA Data wykonania operacji: 2025-06-27 02:00 Oryginalna kwota operacji: 4.50 Numer karty: 425125******0264 (4.50 PLN) | D10: 45837
A11: kawa | B11: 20 | C11: Tytuł: 74838495178316559138442 Lokalizacja: Adres: ALL GOOD S.A. KAWIAR 02 Miasto: WARSZAWA Kraj: POLSKA Data wykonania operacji: 2025-06-27 02:00 Oryginalna kwota operacji: 20.00 Numer karty: 425125******0264 (20.00 PLN) | D11: 45837
A12: fun | B12: 170 | C12: Tytuł: 74810315178161829276198 Lokalizacja: Adres: MUR Miasto: Krakow Kraj: POLSKA Data wykonania operacji: 2025-06-27 02:00 Oryginalna kwota operacji: 170.00 Numer karty: 425125******0264 (170.00 PLN) | D12: 45837
A13: restauracje | B13: 24.3 | C13: Tytuł: 74810315178161776884390 Lokalizacja: Adres: SANDRAS MATCHA Miasto: WARSZAWA Kraj: POLSKA Data wykonania operacji: 2025-06-27 02:00 Oryginalna kwota operacji: 24.30 Numer karty: 425125******0264 (24.30 PLN) | D13: 45837
A14: przejazdy | B14: 149 | C14: Tytuł: 010061097 74463675178501791767764 Lokalizacja: Adres: WWW BILKOM PL Miasto: WARSZAWA Kraj: POLSKA Data wykonania operacji: 2025-06-27 02:00 Oryginalna kwota operacji: 149.00 Numer karty: 425125******0264 (149.00 PLN) | D14: 45837
A15: żabka | B15: 17.49 | C15: Tytuł: 000498849 74230785178170322850918 Lokalizacja: Adres: ZABKA Z8683 K.1 Miasto: WARSZAWA Kraj: POLSKA Data wykonania operacji: 2025-06-27 02:00 Oryginalna kwota operacji: 17.49 Numer karty: 425125******0264 (17.49 PLN) | D15: 45837
A16: restauracje | B16: 48 | C16: Tytuł: 010061097 74169505178651783676816 Lokalizacja: Adres: HAPPA TO MAME Miasto: POZNAN Kraj: POLSKA Data wykonania operacji: 2025-06-27 02:00 Oryginalna kwota operacji: 48.00 Numer karty: 425125******0264 (48.00 PLN) | D16: 45837
A17: kawa | B17: 50 | C17: Tytuł: 74838495178316589744615 Lokalizacja: Adres: ALL GOOD S.A. KAWIAR 02 Miasto: WARSZAWA Kraj: POLSKA Data wykonania operacji: 2025-06-27 02:00 Oryginalna kwota operacji: 50.00 Numer karty: 425125******0264 (50.00 PLN) | D17: 45837
A18: apteka | B18: 50.49 | C18: Tytuł: 74838495177316390018200 Lokalizacja: Adres: ZIKO APTEKA 05 Miasto: Poznan Kraj: POLSKA Data wykonania operacji: 2025-06-26 02:00 Oryginalna kwota operacji: 50.49 Numer karty: 425125******0264 (50.49 PLN) | D18: 45836
A19: żabka | B19: 9.99 | C19: Tytuł: 000498849 74230785177170227140259 Lokalizacja: Adres: ZABKA Z5606 K.2 Miasto: POZNAN Kraj: POLSKA Data wykonania operacji: 2025-06-26 02:00 Oryginalna kwota operacji: 9.99 Numer karty: 425125******0264 (9.99 PLN) | D19: 45836
A20: restauracje | B20: 32 | C20: Tytuł: 74810315177161695044358 Lokalizacja: Adres: RESTAURACJA LORO Miasto: POZNAN Kraj: POLSKA Data wykonania operacji: 2025-06-26 02:00 Oryginalna kwota operacji: 32.00 Numer karty: 425125******0264 (32.00 PLN) | D20: 45836
A21: biedronka | B21: 25.28 | C21: Tytuł: 000498849 74230785177170201527877 Lokalizacja: Adres: NETTO 5304 SCO K.3 Miasto: POZNAN Kraj: POLSKA Data wykonania operacji: 2025-06-25 02:00 Oryginalna kwota operacji: 25.28 Numer karty: 425125******0264 (25.28 PLN) | D21: 45835
... A114: biuro | B114: 381.87 | C114: KANCELARIA PODATKOWO-GOSPODARCZA SP ÓŁKA Z OGRANICZONĄ ODPOWIEDZIALNOŚC IĄ ul. Radomska 7 44-164 Gliwice NI P: PL 631-264-51-93 FA/19/05/2025 | D114: 45811

Sheet maj2025
E1: Przychody | H1: Stan konta na początku miesiąca | J1: Koszty stałe | K1: =SUM(J3:J991) -> 10785.17
A2: kategoria | B2: kwota | C2: opis | D2: data
A3: lekarz | B3: 1560 | C3: Tytuł: 74810315149158741023563 Lokalizacja: Adres: DENTA Miasto: Wroclaw Kraj: POLSKA Data wykonania operacji: 2025-05-29 02:00 Oryginalna kwota operacji: 1560.00 Numer karty: 425125******0264 (1560.00 PLN) | D3: 45808 | E3: sml | F3: 20 516,40 | H3: =Zbiorczy!D59 -> 140997.94 | J3: =SUMIF($A$3:A$197, K3, B$3:B$197) -> 3213.27 | K3: zus | M3: =SUMIF($A$3:A$197, N3, B$3:B$197) -> 558.16 | N3: biedronka
A4: auto | B4: 3.5 | C4: Tytuł: 010061097 74463675149611497725242 Lokalizacja: Adres: KBU SPOLKA Z OGRANICZONA Miasto: STARE MIASTO Kraj: POLSKA Data wykonania operacji: 2025-05-29 02:00 Oryginalna kwota operacji: 3.50 Numer karty: 425125******0264 (3.50 PLN) | D4: 45808 | E4: skąd? | F4: 34640 | J4: =SUMIF($A$3:A$197, K4, B$3:B$197) -> 2456 | K4: PIT36 | M4: =SUMIF($A$3:A$197, N4, B$3:B$197) -> 73.65 | N4: żabka
A5: restauracje | B5: 31 | C5: Tytuł: 000498849 74230785149168259758373 Lokalizacja: Adres: HUMMUS Miasto: WROCLAW Kraj: POLSKA Data wykonania operacji: 2025-05-29 02:00 Oryginalna kwota operacji: 31.00 Numer karty: 425125******0264 (31.00 PLN) | D5: 45808 | E5: sml prezent | J5: =SUMIF($A$3:A$197, K5, B$3:B$197) -> 3373 | K5: VAT | M5: =SUMIF($A$3:A$197, N5, B$3:B$197) -> 2865.09 | N5: auto
A6: rossman | B6: 22.99 | C6: Tytuł: 74838495150312056561667 Lokalizacja: Adres: ROSSMANN 47 Miasto: WROCLAW Kraj: POLSKA Data wykonania operacji: 2025-05-29 02:00 Oryginalna kwota operacji: 22.99 Numer karty: 425125******0264 (22.99 PLN) | D6: 45808 | J6: =SUMIF($A$3:A$197, K6, B$3:B$197) -> 1742.9 | K6: mieszkanie | M6: =SUMIF($A$3:A$197, N6, B$3:B$197) -> 927.33 | N6: paliwo
A7: auto | B7: 19 | C7: Tytuł: 010061097 74463675149591493450021 Lokalizacja: Adres: KBU SP Z O O SPP WROCLAW Miasto: KRAKOW Kraj: POLSKA Data wykonania operacji: 2025-05-29 02:00 Oryginalna kwota operacji: 19.00 Numer karty: 425125******0264 (19.00 PLN) | D7: 45808 | J7: =SUMIF($A$3:A$197, K7, B$3:B$197) -> 0 | K7: kredyt | M7: =SUMIF($A$3:A$197, N7, B$3:B$197) -> 2727.58 | N7: fun
A8: auto | B8: 2 | C8: Tytuł: 010061097 74463675149611497729855 Lokalizacja: Adres: KBU SPOLKA Z OGRANICZONA Miasto: STARE MIASTO Kraj: POLSKA Data wykonania operacji: 2025-05-29 02:00 Oryginalna kwota operacji: 2.00 Numer karty: 425125******0264 (2.00 PLN) | D8: 45808 | M8: =SUMIF($A$3:A$197, N8, B$3:B$197) -> 2865.09 | N8: auto
A9: żabka | B9: 5.5 | C9: Tytuł: 000498849 74230785148168229752903 Lokalizacja: Adres: ZABKA Z1048 K.2 Miasto: POZNAN Kraj: POLSKA Data wykonania operacji: 2025-05-28 02:00 Oryginalna kwota operacji: 5.50 Numer karty: 425125******0264 (5.50 PLN) | D9: 45807
A10: biedronka | B10: 28.58 | C10: Tytuł: 000498849 74230785149168246628283 Lokalizacja: Adres: NETTO 5304 SCO K.3 Miasto: POZNAN Kraj: POLSKA Data wykonania operacji: 2025-05-28 02:00 Oryginalna kwota operacji: 28.58 Numer karty: 425125******0264 (28.58 PLN) | D10: 45807
A11: żabka | B11: 2.99 | C11: Tytuł: 000498849 74230785148168214632060 Lokalizacja: Adres: ZABKA Z5606 K.2 Miasto: POZNAN Kraj: POLSKA Data wykonania operacji: 2025-05-28 02:00 Oryginalna kwota operacji: 2.99 Numer karty: 425125******0264 (2.99 PLN) | D11: 45807
A12: apteka | B12: 24.99 | C12: Tytuł: 74838495148311902336618 Lokalizacja: Adres: ZIKO APTEKA 05 Miasto: Poznan Kraj: POLSKA Data wykonania operacji: 2025-05-28 02:00 Oryginalna kwota operacji: 24.99 Numer karty: 425125******0264 (24.99 PLN) | D12: 45807
A13: biedronka | B13: 49.22 | C13: Tytuł: 000498849 74230785148168179870747 Lokalizacja: Adres: NETTO 5304 SCO K.3 Miasto: POZNAN Kraj: POLSKA Data wykonania operacji: 2025-05-27 02:00 Oryginalna kwota operacji: 49.22 Numer karty: 425125******0264 (49.22 PLN) | D13: 45806
A14: lekarz | B14: 250 | C14: Tytuł: 010061097 74169505146621463413532 Lokalizacja: Adres: PRACOWNIA PSYCHOLOGICZNA Miasto: POZNAN Kraj: POLSKA Data wykonania operacji: 2025-05-26 02:00 Oryginalna kwota operacji: 250.00 Numer karty: 425125******0264 (250.00 PLN) | D14: 45805
A15: fun | B15: 28 | C15: Tytuł: 000498849 74230785144167937006119 Lokalizacja: Adres: TEDI 7184 Miasto: ZABKOWICE SLA Kraj: POLSKA Data wykonania operacji: 2025-05-24 02:00 Oryginalna kwota operacji: 28.00 Numer karty: 425125******0264 (28.00 PLN) | D15: 45804
A16: fun | B16: 12.37 | C16: Tytuł: 010062941 74987505144003341679075 Lokalizacja: Adres: Action A123 Miasto: Zabkowice Sla Kraj: POLSKA Data wykonania operacji: 2025-05-24 02:00 Oryginalna kwota operacji: 12.37 Numer karty: 425125******0264 (12.37 PLN) | D16: 45804
A17: auto | B17: 2 | C17: Tytuł: 010061097 74463675145591452083023 Lokalizacja: Adres: PROCAR WOJCIECH MEDRALA Miasto: NYSA Kraj: POLSKA Data wykonania operacji: 2025-05-24 02:00 Oryginalna kwota operacji: 2.00 Numer karty: 425125******0264 (2.00 PLN) | D17: 45804
A18: auto | B18: 2 | C18: Tytuł: 010061097 74463675145591452083619 Lokalizacja: Adres: PROCAR WOJCIECH MEDRALA Miasto: NYSA Kraj: POLSKA Data wykonania operacji: 2025-05-24 02:00 Oryginalna kwota operacji: 2.00 Numer karty: 425125******0264 (2.00 PLN) | D18: 45804
A19: auto | B19: 5 | C19: Tytuł: 010061097 74463675145591452083551 Lokalizacja: Adres: PROCAR WOJCIECH MEDRALA Miasto: NYSA Kraj: POLSKA Data wykonania operacji: 2025-05-24 02:00 Oryginalna kwota operacji: 5.00 Numer karty: 425125******0264 (5.00 PLN) | D19: 45804
A20: auto | B20: 5 | C20: Tytuł: 010061097 74463675145591452083221 Lokalizacja: Adres: PROCAR WOJCIECH MEDRALA Miasto: NYSA Kraj: POLSKA Data wykonania operacji: 2025-05-24 02:00 Oryginalna kwota operacji: 5.00 Numer karty: 425125******0264 (5.00 PLN) | D20: 45804
... A103: biuro | B103: 381.87 | C103: KANCELARIA PODATKOWO-GOSPODARCZA SP ÓŁKA Z OGRANICZONĄ ODPOWIEDZIALNOŚC IĄ ul. Radomska 7 44-164 Gliwice NI P: PL 631-264-51-93 FA/64/04/2025 | D103: 45779

Sheet kwiecien2025
E1: Przychody | H1: Stan konta na początku miesiąca | J1: Koszty stałe | K1: =SUM(J3:J995) -> 9276.15
A2: kategoria | B2: kwota | C2: opis | D2: data
